2021-08-01 11:27:50,618 ERROR: Exception on /user/rainmaker/popup [GET] [in g:\intercloud\flask\venv\lib\site-packages\flask\app.py:1891]
Traceback (most recent call last):
  File "g:\intercloud\flask\venv\lib\site-packages\flask\app.py", line 2447, in wsgi_app
    response = self.full_dispatch_request()
  File "g:\intercloud\flask\venv\lib\site-packages\flask\app.py", line 1952, in full_dispatch_request
    rv = self.handle_user_exception(e)
  File "g:\intercloud\flask\venv\lib\site-packages\flask\app.py", line 1821, in handle_user_exception
    reraise(exc_type, exc_value, tb)
  File "g:\intercloud\flask\venv\lib\site-packages\flask\_compat.py", line 39, in reraise
    raise value
  File "g:\intercloud\flask\venv\lib\site-packages\flask\app.py", line 1950, in full_dispatch_request
    rv = self.dispatch_request()
  File "g:\intercloud\flask\venv\lib\site-packages\flask\app.py", line 1936, in dispatch_request
    return self.view_functions[rule.endpoint](**req.view_args)
  File "g:\intercloud\flask\venv\lib\site-packages\flask_login\utils.py", line 272, in decorated_view
    return func(*args, **kwargs)
  File "G:\Intercloud\flask\microblog\app\main\routes.py", line 158, in user_popup
    return render_template('user_popup.html',user=user,form=form)
  File "g:\intercloud\flask\venv\lib\site-packages\flask\templating.py", line 138, in render_template
    ctx.app.jinja_env.get_or_select_template(template_name_or_list),
  File "g:\intercloud\flask\venv\lib\site-packages\jinja2\environment.py", line 930, in get_or_select_template
    return self.get_template(template_name_or_list, parent, globals)
  File "g:\intercloud\flask\venv\lib\site-packages\jinja2\environment.py", line 883, in get_template
    return self._load_template(name, self.make_globals(globals))
  File "g:\intercloud\flask\venv\lib\site-packages\jinja2\environment.py", line 857, in _load_template
    template = self.loader.load(self, name, globals)
  File "g:\intercloud\flask\venv\lib\site-packages\jinja2\loaders.py", line 127, in load
    code = environment.compile(source, name, filename)
  File "g:\intercloud\flask\venv\lib\site-packages\jinja2\environment.py", line 638, in compile
    self.handle_exception(source=source_hint)
  File "g:\intercloud\flask\venv\lib\site-packages\jinja2\environment.py", line 832, in handle_exception
    reraise(*rewrite_traceback_stack(source=source))
  File "g:\intercloud\flask\venv\lib\site-packages\jinja2\_compat.py", line 28, in reraise
    raise value.with_traceback(tb)
  File "G:\Intercloud\flask\microblog\app\templates\user_popup.html", line 15, in template
    {{ _('%(count)d following', count=user.followed.count()) }
jinja2.exceptions.TemplateSyntaxError: unexpected '}'
2021-08-01 11:37:30,182 INFO: Microblog startup [in G:\Intercloud\flask\microblog\app\__init__.py:96]
2021-08-01 11:37:30,182 INFO: Microblog startup [in G:\Intercloud\flask\microblog\app\__init__.py:96]
2021-08-01 11:38:46,920 ERROR: Exception on /user/rainmaker/popup [GET] [in g:\intercloud\flask\venv\lib\site-packages\flask\app.py:1891]
Traceback (most recent call last):
  File "g:\intercloud\flask\venv\lib\site-packages\flask\app.py", line 2447, in wsgi_app
    response = self.full_dispatch_request()
  File "g:\intercloud\flask\venv\lib\site-packages\flask\app.py", line 1952, in full_dispatch_request
    rv = self.handle_user_exception(e)
  File "g:\intercloud\flask\venv\lib\site-packages\flask\app.py", line 1821, in handle_user_exception
    reraise(exc_type, exc_value, tb)
  File "g:\intercloud\flask\venv\lib\site-packages\flask\_compat.py", line 39, in reraise
    raise value
  File "g:\intercloud\flask\venv\lib\site-packages\flask\app.py", line 1950, in full_dispatch_request
    rv = self.dispatch_request()
  File "g:\intercloud\flask\venv\lib\site-packages\flask\app.py", line 1936, in dispatch_request
    return self.view_functions[rule.endpoint](**req.view_args)
  File "g:\intercloud\flask\venv\lib\site-packages\flask_login\utils.py", line 272, in decorated_view
    return func(*args, **kwargs)
  File "G:\Intercloud\flask\microblog\app\main\routes.py", line 158, in user_popup
    return render_template('user_popup.html',user=user,form=form)
  File "g:\intercloud\flask\venv\lib\site-packages\flask\templating.py", line 137, in render_template
    return _render(
  File "g:\intercloud\flask\venv\lib\site-packages\flask\templating.py", line 120, in _render
    rv = template.render(context)
  File "g:\intercloud\flask\venv\lib\site-packages\jinja2\environment.py", line 1090, in render
    self.environment.handle_exception()
  File "g:\intercloud\flask\venv\lib\site-packages\jinja2\environment.py", line 832, in handle_exception
    reraise(*rewrite_traceback_stack(source=source))
  File "g:\intercloud\flask\venv\lib\site-packages\jinja2\_compat.py", line 28, in reraise
    raise value.with_traceback(tb)
  File "G:\Intercloud\flask\microblog\app\templates\user_popup.html", line 5, in top-level template code
    <p><a href="{{ url_for('main.user', username=user.username) }}">
  File "g:\intercloud\flask\venv\lib\site-packages\flask\helpers.py", line 370, in url_for
    return appctx.app.handle_url_build_error(error, endpoint, values)
  File "g:\intercloud\flask\venv\lib\site-packages\flask\app.py", line 2216, in handle_url_build_error
    reraise(exc_type, exc_value, tb)
  File "g:\intercloud\flask\venv\lib\site-packages\flask\_compat.py", line 39, in reraise
    raise value
  File "g:\intercloud\flask\venv\lib\site-packages\flask\helpers.py", line 357, in url_for
    rv = url_adapter.build(
  File "g:\intercloud\flask\venv\lib\site-packages\werkzeug\routing.py", line 2179, in build
    raise BuildError(endpoint, values, method, self)
werkzeug.routing.BuildError: Could not build url for endpoint 'main.user' with values ['username']. Did you mean 'main.search' instead?
2021-08-01 11:38:46,920 ERROR: Exception on /user/rainmaker/popup [GET] [in g:\intercloud\flask\venv\lib\site-packages\flask\app.py:1891]
Traceback (most recent call last):
  File "g:\intercloud\flask\venv\lib\site-packages\flask\app.py", line 2447, in wsgi_app
    response = self.full_dispatch_request()
  File "g:\intercloud\flask\venv\lib\site-packages\flask\app.py", line 1952, in full_dispatch_request
    rv = self.handle_user_exception(e)
  File "g:\intercloud\flask\venv\lib\site-packages\flask\app.py", line 1821, in handle_user_exception
    reraise(exc_type, exc_value, tb)
  File "g:\intercloud\flask\venv\lib\site-packages\flask\_compat.py", line 39, in reraise
    raise value
  File "g:\intercloud\flask\venv\lib\site-packages\flask\app.py", line 1950, in full_dispatch_request
    rv = self.dispatch_request()
  File "g:\intercloud\flask\venv\lib\site-packages\flask\app.py", line 1936, in dispatch_request
    return self.view_functions[rule.endpoint](**req.view_args)
  File "g:\intercloud\flask\venv\lib\site-packages\flask_login\utils.py", line 272, in decorated_view
    return func(*args, **kwargs)
  File "G:\Intercloud\flask\microblog\app\main\routes.py", line 158, in user_popup
    return render_template('user_popup.html',user=user,form=form)
  File "g:\intercloud\flask\venv\lib\site-packages\flask\templating.py", line 137, in render_template
    return _render(
  File "g:\intercloud\flask\venv\lib\site-packages\flask\templating.py", line 120, in _render
    rv = template.render(context)
  File "g:\intercloud\flask\venv\lib\site-packages\jinja2\environment.py", line 1090, in render
    self.environment.handle_exception()
  File "g:\intercloud\flask\venv\lib\site-packages\jinja2\environment.py", line 832, in handle_exception
    reraise(*rewrite_traceback_stack(source=source))
  File "g:\intercloud\flask\venv\lib\site-packages\jinja2\_compat.py", line 28, in reraise
    raise value.with_traceback(tb)
  File "G:\Intercloud\flask\microblog\app\templates\user_popup.html", line 5, in top-level template code
    <p><a href="{{ url_for('main.user', username=user.username) }}">
  File "g:\intercloud\flask\venv\lib\site-packages\flask\helpers.py", line 370, in url_for
    return appctx.app.handle_url_build_error(error, endpoint, values)
  File "g:\intercloud\flask\venv\lib\site-packages\flask\app.py", line 2216, in handle_url_build_error
    reraise(exc_type, exc_value, tb)
  File "g:\intercloud\flask\venv\lib\site-packages\flask\_compat.py", line 39, in reraise
    raise value
  File "g:\intercloud\flask\venv\lib\site-packages\flask\helpers.py", line 357, in url_for
    rv = url_adapter.build(
  File "g:\intercloud\flask\venv\lib\site-packages\werkzeug\routing.py", line 2179, in build
    raise BuildError(endpoint, values, method, self)
werkzeug.routing.BuildError: Could not build url for endpoint 'main.user' with values ['username']. Did you mean 'main.search' instead?
2021-08-01 11:39:31,087 INFO: Microblog startup [in G:\Intercloud\flask\microblog\app\__init__.py:96]
2021-08-01 11:39:31,087 INFO: Microblog startup [in G:\Intercloud\flask\microblog\app\__init__.py:96]
