2021-08-01 16:40:38,401 ERROR: Exception on /api/users/3 [GET] [in g:\intercloud\flask\venv\lib\site-packages\flask\app.py:1891]
Traceback (most recent call last):
  File "g:\intercloud\flask\venv\lib\site-packages\flask\app.py", line 2447, in wsgi_app
    response = self.full_dispatch_request()
  File "g:\intercloud\flask\venv\lib\site-packages\flask\app.py", line 1952, in full_dispatch_request
    rv = self.handle_user_exception(e)
  File "g:\intercloud\flask\venv\lib\site-packages\flask\app.py", line 1821, in handle_user_exception
    reraise(exc_type, exc_value, tb)
  File "g:\intercloud\flask\venv\lib\site-packages\flask\_compat.py", line 39, in reraise
    raise value
  File "g:\intercloud\flask\venv\lib\site-packages\flask\app.py", line 1950, in full_dispatch_request
    rv = self.dispatch_request()
  File "g:\intercloud\flask\venv\lib\site-packages\flask\app.py", line 1936, in dispatch_request
    return self.view_functions[rule.endpoint](**req.view_args)
TypeError: get_user() got an unexpected keyword argument 'id'
2021-08-01 16:41:21,311 ERROR: Exception on /api/users/1 [GET] [in g:\intercloud\flask\venv\lib\site-packages\flask\app.py:1891]
Traceback (most recent call last):
  File "g:\intercloud\flask\venv\lib\site-packages\flask\app.py", line 2447, in wsgi_app
    response = self.full_dispatch_request()
  File "g:\intercloud\flask\venv\lib\site-packages\flask\app.py", line 1952, in full_dispatch_request
    rv = self.handle_user_exception(e)
  File "g:\intercloud\flask\venv\lib\site-packages\flask\app.py", line 1821, in handle_user_exception
    reraise(exc_type, exc_value, tb)
  File "g:\intercloud\flask\venv\lib\site-packages\flask\_compat.py", line 39, in reraise
    raise value
  File "g:\intercloud\flask\venv\lib\site-packages\flask\app.py", line 1950, in full_dispatch_request
    rv = self.dispatch_request()
  File "g:\intercloud\flask\venv\lib\site-packages\flask\app.py", line 1936, in dispatch_request
    return self.view_functions[rule.endpoint](**req.view_args)
TypeError: get_user() got an unexpected keyword argument 'id'
2021-08-01 16:41:21,311 ERROR: Exception on /api/users/1 [GET] [in g:\intercloud\flask\venv\lib\site-packages\flask\app.py:1891]
Traceback (most recent call last):
  File "g:\intercloud\flask\venv\lib\site-packages\flask\app.py", line 2447, in wsgi_app
    response = self.full_dispatch_request()
  File "g:\intercloud\flask\venv\lib\site-packages\flask\app.py", line 1952, in full_dispatch_request
    rv = self.handle_user_exception(e)
  File "g:\intercloud\flask\venv\lib\site-packages\flask\app.py", line 1821, in handle_user_exception
    reraise(exc_type, exc_value, tb)
  File "g:\intercloud\flask\venv\lib\site-packages\flask\_compat.py", line 39, in reraise
    raise value
  File "g:\intercloud\flask\venv\lib\site-packages\flask\app.py", line 1950, in full_dispatch_request
    rv = self.dispatch_request()
  File "g:\intercloud\flask\venv\lib\site-packages\flask\app.py", line 1936, in dispatch_request
    return self.view_functions[rule.endpoint](**req.view_args)
TypeError: get_user() got an unexpected keyword argument 'id'
2021-08-01 16:43:22,181 INFO: Microblog startup [in G:\Intercloud\flask\microblog\app\__init__.py:99]
2021-08-01 16:43:22,181 INFO: Microblog startup [in G:\Intercloud\flask\microblog\app\__init__.py:99]
2021-08-01 17:16:36,785 INFO: Microblog startup [in G:\Intercloud\flask\microblog\app\__init__.py:99]
2021-08-01 17:16:36,785 INFO: Microblog startup [in G:\Intercloud\flask\microblog\app\__init__.py:99]
2021-08-01 17:17:02,906 ERROR: Exception on /api/users [GET] [in g:\intercloud\flask\venv\lib\site-packages\flask\app.py:1891]
Traceback (most recent call last):
  File "g:\intercloud\flask\venv\lib\site-packages\flask\app.py", line 2447, in wsgi_app
    response = self.full_dispatch_request()
  File "g:\intercloud\flask\venv\lib\site-packages\flask\app.py", line 1952, in full_dispatch_request
    rv = self.handle_user_exception(e)
  File "g:\intercloud\flask\venv\lib\site-packages\flask\app.py", line 1821, in handle_user_exception
    reraise(exc_type, exc_value, tb)
  File "g:\intercloud\flask\venv\lib\site-packages\flask\_compat.py", line 39, in reraise
    raise value
  File "g:\intercloud\flask\venv\lib\site-packages\flask\app.py", line 1950, in full_dispatch_request
    rv = self.dispatch_request()
  File "g:\intercloud\flask\venv\lib\site-packages\flask\app.py", line 1936, in dispatch_request
    return self.view_functions[rule.endpoint](**req.view_args)
  File "G:\Intercloud\flask\microblog\app\api\users.py", line 13, in get_users
    data = User.to_collection_dict(User.query,page,per_page,'api.get_users')
  File "G:\Intercloud\flask\microblog\app\models.py", line 59, in to_collection_dict
    'items': [item.to_dict() for item in resources.items],
  File "G:\Intercloud\flask\microblog\app\models.py", line 59, in <listcomp>
    'items': [item.to_dict() for item in resources.items],
  File "G:\Intercloud\flask\microblog\app\models.py", line 153, in to_dict
    'last_seen': self.last_seen.isoformat() + 'Z',
AttributeError: 'NoneType' object has no attribute 'isoformat'
2021-08-01 17:17:02,906 ERROR: Exception on /api/users [GET] [in g:\intercloud\flask\venv\lib\site-packages\flask\app.py:1891]
Traceback (most recent call last):
  File "g:\intercloud\flask\venv\lib\site-packages\flask\app.py", line 2447, in wsgi_app
    response = self.full_dispatch_request()
  File "g:\intercloud\flask\venv\lib\site-packages\flask\app.py", line 1952, in full_dispatch_request
    rv = self.handle_user_exception(e)
  File "g:\intercloud\flask\venv\lib\site-packages\flask\app.py", line 1821, in handle_user_exception
    reraise(exc_type, exc_value, tb)
  File "g:\intercloud\flask\venv\lib\site-packages\flask\_compat.py", line 39, in reraise
    raise value
  File "g:\intercloud\flask\venv\lib\site-packages\flask\app.py", line 1950, in full_dispatch_request
    rv = self.dispatch_request()
  File "g:\intercloud\flask\venv\lib\site-packages\flask\app.py", line 1936, in dispatch_request
    return self.view_functions[rule.endpoint](**req.view_args)
  File "G:\Intercloud\flask\microblog\app\api\users.py", line 13, in get_users
    data = User.to_collection_dict(User.query,page,per_page,'api.get_users')
  File "G:\Intercloud\flask\microblog\app\models.py", line 59, in to_collection_dict
    'items': [item.to_dict() for item in resources.items],
  File "G:\Intercloud\flask\microblog\app\models.py", line 59, in <listcomp>
    'items': [item.to_dict() for item in resources.items],
  File "G:\Intercloud\flask\microblog\app\models.py", line 153, in to_dict
    'last_seen': self.last_seen.isoformat() + 'Z',
AttributeError: 'NoneType' object has no attribute 'isoformat'
2021-08-01 17:26:48,431 INFO: Microblog startup [in G:\Intercloud\flask\microblog\app\__init__.py:99]
2021-08-01 17:26:48,431 INFO: Microblog startup [in G:\Intercloud\flask\microblog\app\__init__.py:99]
2021-08-01 17:40:11,654 ERROR: Exception on /api/users/6 [PUT] [in g:\intercloud\flask\venv\lib\site-packages\flask\app.py:1891]
Traceback (most recent call last):
  File "g:\intercloud\flask\venv\lib\site-packages\flask\app.py", line 2447, in wsgi_app
    response = self.full_dispatch_request()
  File "g:\intercloud\flask\venv\lib\site-packages\flask\app.py", line 1953, in full_dispatch_request
    return self.finalize_request(rv)
  File "g:\intercloud\flask\venv\lib\site-packages\flask\app.py", line 1968, in finalize_request
    response = self.make_response(rv)
  File "g:\intercloud\flask\venv\lib\site-packages\flask\app.py", line 2097, in make_response
    raise TypeError(
TypeError: The view function did not return a valid response. The function either returned None or ended without a return statement.
2021-08-01 17:40:11,654 ERROR: Exception on /api/users/6 [PUT] [in g:\intercloud\flask\venv\lib\site-packages\flask\app.py:1891]
Traceback (most recent call last):
  File "g:\intercloud\flask\venv\lib\site-packages\flask\app.py", line 2447, in wsgi_app
    response = self.full_dispatch_request()
  File "g:\intercloud\flask\venv\lib\site-packages\flask\app.py", line 1953, in full_dispatch_request
    return self.finalize_request(rv)
  File "g:\intercloud\flask\venv\lib\site-packages\flask\app.py", line 1968, in finalize_request
    response = self.make_response(rv)
  File "g:\intercloud\flask\venv\lib\site-packages\flask\app.py", line 2097, in make_response
    raise TypeError(
TypeError: The view function did not return a valid response. The function either returned None or ended without a return statement.
2021-08-01 17:40:37,122 INFO: Microblog startup [in G:\Intercloud\flask\microblog\app\__init__.py:99]
2021-08-01 17:40:37,122 INFO: Microblog startup [in G:\Intercloud\flask\microblog\app\__init__.py:99]
2021-08-02 10:15:04,744 INFO: Microblog startup [in G:\Intercloud\flask\microblog\app\__init__.py:99]
2021-08-02 10:15:04,744 INFO: Microblog startup [in G:\Intercloud\flask\microblog\app\__init__.py:99]
2021-08-02 10:15:24,678 INFO: Microblog startup [in G:\Intercloud\flask\microblog\app\__init__.py:99]
2021-08-02 10:15:24,678 INFO: Microblog startup [in G:\Intercloud\flask\microblog\app\__init__.py:99]
2021-08-02 10:15:35,041 INFO: Microblog startup [in G:\Intercloud\flask\microblog\app\__init__.py:99]
2021-08-02 10:15:35,041 INFO: Microblog startup [in G:\Intercloud\flask\microblog\app\__init__.py:99]
2021-08-02 12:10:59,121 INFO: Microblog startup [in G:\Intercloud\flask\microblog\app\__init__.py:99]
2021-08-02 12:10:59,121 INFO: Microblog startup [in G:\Intercloud\flask\microblog\app\__init__.py:99]
2021-08-02 12:16:26,501 INFO: Microblog startup [in G:\Intercloud\flask\microblog\app\__init__.py:99]
2021-08-02 12:16:26,501 INFO: Microblog startup [in G:\Intercloud\flask\microblog\app\__init__.py:99]
2021-08-02 12:29:43,291 INFO: Microblog startup [in G:\Intercloud\flask\microblog\app\__init__.py:99]
2021-08-02 12:29:43,291 INFO: Microblog startup [in G:\Intercloud\flask\microblog\app\__init__.py:99]
