2021-07-29 16:33:40,779 ERROR: Exception on /auth/register [POST] [in g:\intercloud\flask\venv\lib\site-packages\flask\app.py:1891]
Traceback (most recent call last):
  File "g:\intercloud\flask\venv\lib\site-packages\sqlalchemy\engine\base.py", line 1771, in _execute_context
    self.dialect.do_execute(
  File "g:\intercloud\flask\venv\lib\site-packages\sqlalchemy\engine\default.py", line 717, in do_execute
    cursor.execute(statement, parameters)
sqlite3.OperationalError: no such table: user

The above exception was the direct cause of the following exception:

Traceback (most recent call last):
  File "g:\intercloud\flask\venv\lib\site-packages\flask\app.py", line 2447, in wsgi_app
    response = self.full_dispatch_request()
  File "g:\intercloud\flask\venv\lib\site-packages\flask\app.py", line 1952, in full_dispatch_request
    rv = self.handle_user_exception(e)
  File "g:\intercloud\flask\venv\lib\site-packages\flask\app.py", line 1821, in handle_user_exception
    reraise(exc_type, exc_value, tb)
  File "g:\intercloud\flask\venv\lib\site-packages\flask\_compat.py", line 39, in reraise
    raise value
  File "g:\intercloud\flask\venv\lib\site-packages\flask\app.py", line 1950, in full_dispatch_request
    rv = self.dispatch_request()
  File "g:\intercloud\flask\venv\lib\site-packages\flask\app.py", line 1936, in dispatch_request
    return self.view_functions[rule.endpoint](**req.view_args)
  File "G:\Intercloud\flask\microblog\app\auth\routes.py", line 42, in register
    if form.validate_on_submit():
  File "g:\intercloud\flask\venv\lib\site-packages\flask_wtf\form.py", line 100, in validate_on_submit
    return self.is_submitted() and self.validate()
  File "g:\intercloud\flask\venv\lib\site-packages\wtforms\form.py", line 318, in validate
    return super(Form, self).validate(extra)
  File "g:\intercloud\flask\venv\lib\site-packages\wtforms\form.py", line 150, in validate
    if not field.validate(self, extra):
  File "g:\intercloud\flask\venv\lib\site-packages\wtforms\fields\core.py", line 226, in validate
    stop_validation = self._run_validation_chain(form, chain)
  File "g:\intercloud\flask\venv\lib\site-packages\wtforms\fields\core.py", line 246, in _run_validation_chain
    validator(form, self)
  File "G:\Intercloud\flask\microblog\app\auth\forms.py", line 25, in validate_username
    user = User.query.filter_by(username=username.data).first()
  File "g:\intercloud\flask\venv\lib\site-packages\sqlalchemy\orm\query.py", line 2763, in first
    return self.limit(1)._iter().first()
  File "g:\intercloud\flask\venv\lib\site-packages\sqlalchemy\orm\query.py", line 2847, in _iter
    result = self.session.execute(
  File "g:\intercloud\flask\venv\lib\site-packages\sqlalchemy\orm\session.py", line 1689, in execute
    result = conn._execute_20(statement, params or {}, execution_options)
  File "g:\intercloud\flask\venv\lib\site-packages\sqlalchemy\engine\base.py", line 1583, in _execute_20
    return meth(self, args_10style, kwargs_10style, execution_options)
  File "g:\intercloud\flask\venv\lib\site-packages\sqlalchemy\sql\elements.py", line 323, in _execute_on_connection
    return connection._execute_clauseelement(
  File "g:\intercloud\flask\venv\lib\site-packages\sqlalchemy\engine\base.py", line 1452, in _execute_clauseelement
    ret = self._execute_context(
  File "g:\intercloud\flask\venv\lib\site-packages\sqlalchemy\engine\base.py", line 1814, in _execute_context
    self._handle_dbapi_exception(
  File "g:\intercloud\flask\venv\lib\site-packages\sqlalchemy\engine\base.py", line 1995, in _handle_dbapi_exception
    util.raise_(
  File "g:\intercloud\flask\venv\lib\site-packages\sqlalchemy\util\compat.py", line 207, in raise_
    raise exception
  File "g:\intercloud\flask\venv\lib\site-packages\sqlalchemy\engine\base.py", line 1771, in _execute_context
    self.dialect.do_execute(
  File "g:\intercloud\flask\venv\lib\site-packages\sqlalchemy\engine\default.py", line 717, in do_execute
    cursor.execute(statement, parameters)
sqlalchemy.exc.OperationalError: (sqlite3.OperationalError) no such table: user
[SQL: SELECT user.id AS user_id, user.username AS user_username, user.email AS user_email, user.password_hash AS user_password_hash, user.about_me AS user_about_me, user.last_seen AS user_last_seen 
FROM user 
WHERE user.username = ?
 LIMIT ? OFFSET ?]
[parameters: ('simon', 1, 0)]
(Background on this error at: https://sqlalche.me/e/14/e3q8)
2021-07-29 16:40:33,692 INFO: Microblog startup [in G:\Intercloud\flask\microblog\app\__init__.py:96]
2021-07-29 16:40:33,692 INFO: Microblog startup [in G:\Intercloud\flask\microblog\app\__init__.py:96]
2021-07-29 16:40:45,749 ERROR: Exception on /auth/login [POST] [in g:\intercloud\flask\venv\lib\site-packages\flask\app.py:1891]
Traceback (most recent call last):
  File "g:\intercloud\flask\venv\lib\site-packages\sqlalchemy\engine\base.py", line 1771, in _execute_context
    self.dialect.do_execute(
  File "g:\intercloud\flask\venv\lib\site-packages\sqlalchemy\engine\default.py", line 717, in do_execute
    cursor.execute(statement, parameters)
sqlite3.OperationalError: no such table: user

The above exception was the direct cause of the following exception:

Traceback (most recent call last):
  File "g:\intercloud\flask\venv\lib\site-packages\flask\app.py", line 2447, in wsgi_app
    response = self.full_dispatch_request()
  File "g:\intercloud\flask\venv\lib\site-packages\flask\app.py", line 1952, in full_dispatch_request
    rv = self.handle_user_exception(e)
  File "g:\intercloud\flask\venv\lib\site-packages\flask\app.py", line 1821, in handle_user_exception
    reraise(exc_type, exc_value, tb)
  File "g:\intercloud\flask\venv\lib\site-packages\flask\_compat.py", line 39, in reraise
    raise value
  File "g:\intercloud\flask\venv\lib\site-packages\flask\app.py", line 1950, in full_dispatch_request
    rv = self.dispatch_request()
  File "g:\intercloud\flask\venv\lib\site-packages\flask\app.py", line 1936, in dispatch_request
    return self.view_functions[rule.endpoint](**req.view_args)
  File "G:\Intercloud\flask\microblog\app\auth\routes.py", line 19, in login
    user = User.query.filter_by(username=form.username.data).first()
  File "g:\intercloud\flask\venv\lib\site-packages\sqlalchemy\orm\query.py", line 2763, in first
    return self.limit(1)._iter().first()
  File "g:\intercloud\flask\venv\lib\site-packages\sqlalchemy\orm\query.py", line 2847, in _iter
    result = self.session.execute(
  File "g:\intercloud\flask\venv\lib\site-packages\sqlalchemy\orm\session.py", line 1689, in execute
    result = conn._execute_20(statement, params or {}, execution_options)
  File "g:\intercloud\flask\venv\lib\site-packages\sqlalchemy\engine\base.py", line 1583, in _execute_20
    return meth(self, args_10style, kwargs_10style, execution_options)
  File "g:\intercloud\flask\venv\lib\site-packages\sqlalchemy\sql\elements.py", line 323, in _execute_on_connection
    return connection._execute_clauseelement(
  File "g:\intercloud\flask\venv\lib\site-packages\sqlalchemy\engine\base.py", line 1452, in _execute_clauseelement
    ret = self._execute_context(
  File "g:\intercloud\flask\venv\lib\site-packages\sqlalchemy\engine\base.py", line 1814, in _execute_context
    self._handle_dbapi_exception(
  File "g:\intercloud\flask\venv\lib\site-packages\sqlalchemy\engine\base.py", line 1995, in _handle_dbapi_exception
    util.raise_(
  File "g:\intercloud\flask\venv\lib\site-packages\sqlalchemy\util\compat.py", line 207, in raise_
    raise exception
  File "g:\intercloud\flask\venv\lib\site-packages\sqlalchemy\engine\base.py", line 1771, in _execute_context
    self.dialect.do_execute(
  File "g:\intercloud\flask\venv\lib\site-packages\sqlalchemy\engine\default.py", line 717, in do_execute
    cursor.execute(statement, parameters)
sqlalchemy.exc.OperationalError: (sqlite3.OperationalError) no such table: user
[SQL: SELECT user.id AS user_id, user.username AS user_username, user.email AS user_email, user.password_hash AS user_password_hash, user.about_me AS user_about_me, user.last_seen AS user_last_seen 
FROM user 
WHERE user.username = ?
 LIMIT ? OFFSET ?]
[parameters: ('rainmaker', 1, 0)]
(Background on this error at: https://sqlalche.me/e/14/e3q8)
2021-07-29 16:43:32,252 INFO: Microblog startup [in G:\Intercloud\flask\microblog\app\__init__.py:96]
2021-07-29 16:43:32,252 INFO: Microblog startup [in G:\Intercloud\flask\microblog\app\__init__.py:96]
